[2024-04-05T23:30:53.244+0000] {taskinstance.py:1979} INFO - Dependencies all met for dep_context=non-requeueable deps ti=<TaskInstance: extract_osm_farmland.load_farmland_from_api manual__2024-04-05T23:30:49.270588+00:00 [queued]>
[2024-04-05T23:30:53.269+0000] {taskinstance.py:1979} INFO - Dependencies all met for dep_context=requeueable deps ti=<TaskInstance: extract_osm_farmland.load_farmland_from_api manual__2024-04-05T23:30:49.270588+00:00 [queued]>
[2024-04-05T23:30:53.270+0000] {taskinstance.py:2193} INFO - Starting attempt 1 of 2
[2024-04-05T23:30:53.310+0000] {taskinstance.py:2217} INFO - Executing <Task(_PythonDecoratedOperator): load_farmland_from_api> on 2024-04-05 23:30:49.270588+00:00
[2024-04-05T23:30:53.320+0000] {standard_task_runner.py:60} INFO - Started process 2544 to run task
[2024-04-05T23:30:53.334+0000] {standard_task_runner.py:87} INFO - Running: ['***', 'tasks', 'run', 'extract_osm_farmland', 'load_farmland_from_api', 'manual__2024-04-05T23:30:49.270588+00:00', '--job-id', '287', '--raw', '--subdir', 'DAGS_FOLDER/extract_file_data_from_osm.py', '--cfg-path', '/tmp/tmpfdt2357z']
[2024-04-05T23:30:53.337+0000] {standard_task_runner.py:88} INFO - Job 287: Subtask load_farmland_from_api
[2024-04-05T23:30:53.452+0000] {task_command.py:423} INFO - Running <TaskInstance: extract_osm_farmland.load_farmland_from_api manual__2024-04-05T23:30:49.270588+00:00 [running]> on host 2adb4d880117
[2024-04-05T23:30:53.627+0000] {taskinstance.py:2513} INFO - Exporting env vars: AIRFLOW_CTX_DAG_OWNER='***' AIRFLOW_CTX_DAG_ID='extract_osm_farmland' AIRFLOW_CTX_TASK_ID='load_farmland_from_api' AIRFLOW_CTX_EXECUTION_DATE='2024-04-05T23:30:49.270588+00:00' AIRFLOW_CTX_TRY_NUMBER='1' AIRFLOW_CTX_DAG_RUN_ID='manual__2024-04-05T23:30:49.270588+00:00'
[2024-04-05T23:31:01.645+0000] {taskinstance.py:2731} ERROR - Task failed with exception
Traceback (most recent call last):
  File "/home/airflow/.local/lib/python3.8/site-packages/urllib3/connection.py", line 174, in _new_conn
    conn = connection.create_connection(
  File "/home/airflow/.local/lib/python3.8/site-packages/urllib3/util/connection.py", line 72, in create_connection
    for res in socket.getaddrinfo(host, port, family, socket.SOCK_STREAM):
  File "/usr/local/lib/python3.8/socket.py", line 918, in getaddrinfo
    for res in _socket.getaddrinfo(host, port, family, type, proto, flags):
socket.gaierror: [Errno -3] Temporary failure in name resolution

During handling of the above exception, another exception occurred:

Traceback (most recent call last):
  File "/home/airflow/.local/lib/python3.8/site-packages/urllib3/connectionpool.py", line 715, in urlopen
    httplib_response = self._make_request(
  File "/home/airflow/.local/lib/python3.8/site-packages/urllib3/connectionpool.py", line 416, in _make_request
    conn.request(method, url, **httplib_request_kw)
  File "/home/airflow/.local/lib/python3.8/site-packages/urllib3/connection.py", line 244, in request
    super(HTTPConnection, self).request(method, url, body=body, headers=headers)
  File "/usr/local/lib/python3.8/http/client.py", line 1256, in request
    self._send_request(method, url, body, headers, encode_chunked)
  File "/usr/local/lib/python3.8/http/client.py", line 1302, in _send_request
    self.endheaders(body, encode_chunked=encode_chunked)
  File "/usr/local/lib/python3.8/http/client.py", line 1251, in endheaders
    self._send_output(message_body, encode_chunked=encode_chunked)
  File "/usr/local/lib/python3.8/http/client.py", line 1011, in _send_output
    self.send(msg)
  File "/usr/local/lib/python3.8/http/client.py", line 951, in send
    self.connect()
  File "/home/airflow/.local/lib/python3.8/site-packages/urllib3/connection.py", line 205, in connect
    conn = self._new_conn()
  File "/home/airflow/.local/lib/python3.8/site-packages/urllib3/connection.py", line 186, in _new_conn
    raise NewConnectionError(
urllib3.exceptions.NewConnectionError: <urllib3.connection.HTTPConnection object at 0x7fe8a7ae2af0>: Failed to establish a new connection: [Errno -3] Temporary failure in name resolution

During handling of the above exception, another exception occurred:

Traceback (most recent call last):
  File "/home/airflow/.local/lib/python3.8/site-packages/requests/adapters.py", line 486, in send
    resp = conn.urlopen(
  File "/home/airflow/.local/lib/python3.8/site-packages/urllib3/connectionpool.py", line 799, in urlopen
    retries = retries.increment(
  File "/home/airflow/.local/lib/python3.8/site-packages/urllib3/util/retry.py", line 592, in increment
    raise MaxRetryError(_pool, url, error or ResponseError(cause))
urllib3.exceptions.MaxRetryError: HTTPConnectionPool(host='overpass-api.de', port=80): Max retries exceeded with url: /api/interpreter?data=%0A++++++++++++++++%5Bout%3Ajson%5D%5Btimeout%3A50%5D%3B%0A++++++++++++++++area%5B%22ISO3166-1%22%3D%22NG%22%5D%5Badmin_level%3D2%5D%3B%0A++++++++++++++++%28%0A++++++++++++++++way%5B%22landuse%22%3D%22farmland%22%5D%28area%29%3B%0A++++++++++++++++relation%5B%22landuse%22%3D%22farmland%22%5D%28area%29%3B%0A++++++++++++++++%29%3B%0A++++++++++++++++%28._%3B%3E%3B%29%3B%0A++++++++++++++++out+body%3B++++ (Caused by NewConnectionError('<urllib3.connection.HTTPConnection object at 0x7fe8a7ae2af0>: Failed to establish a new connection: [Errno -3] Temporary failure in name resolution'))

During handling of the above exception, another exception occurred:

Traceback (most recent call last):
  File "/home/airflow/.local/lib/python3.8/site-packages/airflow/models/taskinstance.py", line 444, in _execute_task
    result = _execute_callable(context=context, **execute_callable_kwargs)
  File "/home/airflow/.local/lib/python3.8/site-packages/airflow/models/taskinstance.py", line 414, in _execute_callable
    return execute_callable(context=context, **execute_callable_kwargs)
  File "/home/airflow/.local/lib/python3.8/site-packages/airflow/decorators/base.py", line 241, in execute
    return_value = super().execute(context)
  File "/home/airflow/.local/lib/python3.8/site-packages/airflow/operators/python.py", line 200, in execute
    return_value = self.execute_callable()
  File "/home/airflow/.local/lib/python3.8/site-packages/airflow/operators/python.py", line 217, in execute_callable
    return self.python_callable(*self.op_args, **self.op_kwargs)
  File "/opt/airflow/dags/extract_file_data_from_osm.py", line 59, in load_farmland_from_api
    response = requests.get(OVERPASS_URL, params={'data': OVERPASS_QUERY})
  File "/home/airflow/.local/lib/python3.8/site-packages/requests/api.py", line 73, in get
    return request("get", url, params=params, **kwargs)
  File "/home/airflow/.local/lib/python3.8/site-packages/requests/api.py", line 59, in request
    return session.request(method=method, url=url, **kwargs)
  File "/home/airflow/.local/lib/python3.8/site-packages/requests/sessions.py", line 589, in request
    resp = self.send(prep, **send_kwargs)
  File "/home/airflow/.local/lib/python3.8/site-packages/requests/sessions.py", line 703, in send
    r = adapter.send(request, **kwargs)
  File "/home/airflow/.local/lib/python3.8/site-packages/requests/adapters.py", line 519, in send
    raise ConnectionError(e, request=request)
requests.exceptions.ConnectionError: HTTPConnectionPool(host='overpass-api.de', port=80): Max retries exceeded with url: /api/interpreter?data=%0A++++++++++++++++%5Bout%3Ajson%5D%5Btimeout%3A50%5D%3B%0A++++++++++++++++area%5B%22ISO3166-1%22%3D%22NG%22%5D%5Badmin_level%3D2%5D%3B%0A++++++++++++++++%28%0A++++++++++++++++way%5B%22landuse%22%3D%22farmland%22%5D%28area%29%3B%0A++++++++++++++++relation%5B%22landuse%22%3D%22farmland%22%5D%28area%29%3B%0A++++++++++++++++%29%3B%0A++++++++++++++++%28._%3B%3E%3B%29%3B%0A++++++++++++++++out+body%3B++++ (Caused by NewConnectionError('<urllib3.connection.HTTPConnection object at 0x7fe8a7ae2af0>: Failed to establish a new connection: [Errno -3] Temporary failure in name resolution'))
[2024-04-05T23:31:01.663+0000] {taskinstance.py:1149} INFO - Marking task as UP_FOR_RETRY. dag_id=extract_osm_farmland, task_id=load_farmland_from_api, execution_date=20240405T233049, start_date=20240405T233053, end_date=20240405T233101
[2024-04-05T23:31:01.682+0000] {standard_task_runner.py:107} ERROR - Failed to execute job 287 for task load_farmland_from_api (HTTPConnectionPool(host='overpass-api.de', port=80): Max retries exceeded with url: /api/interpreter?data=%0A++++++++++++++++%5Bout%3Ajson%5D%5Btimeout%3A50%5D%3B%0A++++++++++++++++area%5B%22ISO3166-1%22%3D%22NG%22%5D%5Badmin_level%3D2%5D%3B%0A++++++++++++++++%28%0A++++++++++++++++way%5B%22landuse%22%3D%22farmland%22%5D%28area%29%3B%0A++++++++++++++++relation%5B%22landuse%22%3D%22farmland%22%5D%28area%29%3B%0A++++++++++++++++%29%3B%0A++++++++++++++++%28._%3B%3E%3B%29%3B%0A++++++++++++++++out+body%3B++++ (Caused by NewConnectionError('<urllib3.connection.HTTPConnection object at 0x7fe8a7ae2af0>: Failed to establish a new connection: [Errno -3] Temporary failure in name resolution')); 2544)
[2024-04-05T23:31:01.710+0000] {local_task_job_runner.py:234} INFO - Task exited with return code 1
[2024-04-05T23:31:01.736+0000] {taskinstance.py:3312} INFO - 0 downstream tasks scheduled from follow-on schedule check
