[2024-04-05T14:43:29.571+0000] {taskinstance.py:1979} INFO - Dependencies all met for dep_context=non-requeueable deps ti=<TaskInstance: extract_osm_farmland.transform_load_togcs manual__2024-04-05T14:41:57.262286+00:00 [queued]>
[2024-04-05T14:43:29.593+0000] {taskinstance.py:1979} INFO - Dependencies all met for dep_context=requeueable deps ti=<TaskInstance: extract_osm_farmland.transform_load_togcs manual__2024-04-05T14:41:57.262286+00:00 [queued]>
[2024-04-05T14:43:29.594+0000] {taskinstance.py:2193} INFO - Starting attempt 1 of 2
[2024-04-05T14:43:29.647+0000] {taskinstance.py:2217} INFO - Executing <Task(_PythonDecoratedOperator): transform_load_togcs> on 2024-04-05 14:41:57.262286+00:00
[2024-04-05T14:43:29.664+0000] {standard_task_runner.py:60} INFO - Started process 4898 to run task
[2024-04-05T14:43:29.676+0000] {standard_task_runner.py:87} INFO - Running: ['***', 'tasks', 'run', 'extract_osm_farmland', 'transform_load_togcs', 'manual__2024-04-05T14:41:57.262286+00:00', '--job-id', '213', '--raw', '--subdir', 'DAGS_FOLDER/extract_file_data_from_osm.py', '--cfg-path', '/tmp/tmp7pwpmagn']
[2024-04-05T14:43:29.680+0000] {standard_task_runner.py:88} INFO - Job 213: Subtask transform_load_togcs
[2024-04-05T14:43:29.839+0000] {task_command.py:423} INFO - Running <TaskInstance: extract_osm_farmland.transform_load_togcs manual__2024-04-05T14:41:57.262286+00:00 [running]> on host 2adb4d880117
[2024-04-05T14:43:30.118+0000] {taskinstance.py:2513} INFO - Exporting env vars: AIRFLOW_CTX_DAG_OWNER='***' AIRFLOW_CTX_DAG_ID='extract_osm_farmland' AIRFLOW_CTX_TASK_ID='transform_load_togcs' AIRFLOW_CTX_EXECUTION_DATE='2024-04-05T14:41:57.262286+00:00' AIRFLOW_CTX_TRY_NUMBER='1' AIRFLOW_CTX_DAG_RUN_ID='manual__2024-04-05T14:41:57.262286+00:00'
[2024-04-05T14:47:33.282+0000] {taskinstance.py:2731} ERROR - Task failed with exception
Traceback (most recent call last):
  File "/home/airflow/.local/lib/python3.8/site-packages/urllib3/connectionpool.py", line 715, in urlopen
    httplib_response = self._make_request(
  File "/home/airflow/.local/lib/python3.8/site-packages/urllib3/connectionpool.py", line 416, in _make_request
    conn.request(method, url, **httplib_request_kw)
  File "/home/airflow/.local/lib/python3.8/site-packages/urllib3/connection.py", line 244, in request
    super(HTTPConnection, self).request(method, url, body=body, headers=headers)
  File "/usr/local/lib/python3.8/http/client.py", line 1256, in request
    self._send_request(method, url, body, headers, encode_chunked)
  File "/usr/local/lib/python3.8/http/client.py", line 1302, in _send_request
    self.endheaders(body, encode_chunked=encode_chunked)
  File "/usr/local/lib/python3.8/http/client.py", line 1251, in endheaders
    self._send_output(message_body, encode_chunked=encode_chunked)
  File "/usr/local/lib/python3.8/http/client.py", line 1050, in _send_output
    self.send(chunk)
  File "/usr/local/lib/python3.8/http/client.py", line 972, in send
    self.sock.sendall(data)
  File "/usr/local/lib/python3.8/ssl.py", line 1237, in sendall
    v = self.send(byte_view[count:])
  File "/usr/local/lib/python3.8/ssl.py", line 1206, in send
    return self._sslobj.write(data)
socket.timeout: The write operation timed out

During handling of the above exception, another exception occurred:

Traceback (most recent call last):
  File "/home/airflow/.local/lib/python3.8/site-packages/requests/adapters.py", line 486, in send
    resp = conn.urlopen(
  File "/home/airflow/.local/lib/python3.8/site-packages/urllib3/connectionpool.py", line 799, in urlopen
    retries = retries.increment(
  File "/home/airflow/.local/lib/python3.8/site-packages/urllib3/util/retry.py", line 550, in increment
    raise six.reraise(type(error), error, _stacktrace)
  File "/home/airflow/.local/lib/python3.8/site-packages/urllib3/packages/six.py", line 769, in reraise
    raise value.with_traceback(tb)
  File "/home/airflow/.local/lib/python3.8/site-packages/urllib3/connectionpool.py", line 715, in urlopen
    httplib_response = self._make_request(
  File "/home/airflow/.local/lib/python3.8/site-packages/urllib3/connectionpool.py", line 416, in _make_request
    conn.request(method, url, **httplib_request_kw)
  File "/home/airflow/.local/lib/python3.8/site-packages/urllib3/connection.py", line 244, in request
    super(HTTPConnection, self).request(method, url, body=body, headers=headers)
  File "/usr/local/lib/python3.8/http/client.py", line 1256, in request
    self._send_request(method, url, body, headers, encode_chunked)
  File "/usr/local/lib/python3.8/http/client.py", line 1302, in _send_request
    self.endheaders(body, encode_chunked=encode_chunked)
  File "/usr/local/lib/python3.8/http/client.py", line 1251, in endheaders
    self._send_output(message_body, encode_chunked=encode_chunked)
  File "/usr/local/lib/python3.8/http/client.py", line 1050, in _send_output
    self.send(chunk)
  File "/usr/local/lib/python3.8/http/client.py", line 972, in send
    self.sock.sendall(data)
  File "/usr/local/lib/python3.8/ssl.py", line 1237, in sendall
    v = self.send(byte_view[count:])
  File "/usr/local/lib/python3.8/ssl.py", line 1206, in send
    return self._sslobj.write(data)
urllib3.exceptions.ProtocolError: ('Connection aborted.', timeout('The write operation timed out'))

During handling of the above exception, another exception occurred:

Traceback (most recent call last):
  File "/home/airflow/.local/lib/python3.8/site-packages/airflow/models/taskinstance.py", line 444, in _execute_task
    result = _execute_callable(context=context, **execute_callable_kwargs)
  File "/home/airflow/.local/lib/python3.8/site-packages/airflow/models/taskinstance.py", line 414, in _execute_callable
    return execute_callable(context=context, **execute_callable_kwargs)
  File "/home/airflow/.local/lib/python3.8/site-packages/airflow/decorators/base.py", line 241, in execute
    return_value = super().execute(context)
  File "/home/airflow/.local/lib/python3.8/site-packages/airflow/operators/python.py", line 200, in execute
    return_value = self.execute_callable()
  File "/home/airflow/.local/lib/python3.8/site-packages/airflow/operators/python.py", line 217, in execute_callable
    return self.python_callable(*self.op_args, **self.op_kwargs)
  File "/opt/airflow/dags/extract_file_data_from_osm.py", line 90, in transform_load_togcs
    upload_geodataframe_to_gcs(gdf_joined, GCS_BUCKET, GCS_RESULT_PATH)
  File "/opt/airflow/dags/utils.py", line 28, in upload_geodataframe_to_gcs
    blob.upload_from_string(geojson_str)
  File "/home/airflow/.local/lib/python3.8/site-packages/google/cloud/storage/blob.py", line 3089, in upload_from_string
    self.upload_from_file(
  File "/home/airflow/.local/lib/python3.8/site-packages/google/cloud/storage/blob.py", line 2796, in upload_from_file
    self._prep_and_do_upload(
  File "/home/airflow/.local/lib/python3.8/site-packages/google/cloud/storage/blob.py", line 2637, in _prep_and_do_upload
    created_json = self._do_upload(
  File "/home/airflow/.local/lib/python3.8/site-packages/google/cloud/storage/blob.py", line 2443, in _do_upload
    response = self._do_multipart_upload(
  File "/home/airflow/.local/lib/python3.8/site-packages/google/cloud/storage/blob.py", line 1956, in _do_multipart_upload
    response = upload.transmit(
  File "/home/airflow/.local/lib/python3.8/site-packages/google/resumable_media/requests/upload.py", line 153, in transmit
    return _request_helpers.wait_and_retry(
  File "/home/airflow/.local/lib/python3.8/site-packages/google/resumable_media/requests/_request_helpers.py", line 178, in wait_and_retry
    raise error
  File "/home/airflow/.local/lib/python3.8/site-packages/google/resumable_media/requests/_request_helpers.py", line 155, in wait_and_retry
    response = func()
  File "/home/airflow/.local/lib/python3.8/site-packages/google/resumable_media/requests/upload.py", line 145, in retriable_request
    result = transport.request(
  File "/home/airflow/.local/lib/python3.8/site-packages/google/auth/transport/requests.py", line 541, in request
    response = super(AuthorizedSession, self).request(
  File "/home/airflow/.local/lib/python3.8/site-packages/requests/sessions.py", line 589, in request
    resp = self.send(prep, **send_kwargs)
  File "/home/airflow/.local/lib/python3.8/site-packages/requests/sessions.py", line 703, in send
    r = adapter.send(request, **kwargs)
  File "/home/airflow/.local/lib/python3.8/site-packages/requests/adapters.py", line 501, in send
    raise ConnectionError(err, request=request)
requests.exceptions.ConnectionError: ('Connection aborted.', timeout('The write operation timed out'))
[2024-04-05T14:47:33.387+0000] {taskinstance.py:1149} INFO - Marking task as UP_FOR_RETRY. dag_id=extract_osm_farmland, task_id=transform_load_togcs, execution_date=20240405T144157, start_date=20240405T144329, end_date=20240405T144733
[2024-04-05T14:47:33.445+0000] {standard_task_runner.py:107} ERROR - Failed to execute job 213 for task transform_load_togcs (('Connection aborted.', timeout('The write operation timed out')); 4898)
[2024-04-05T14:47:33.569+0000] {local_task_job_runner.py:234} INFO - Task exited with return code 1
[2024-04-05T14:47:33.676+0000] {taskinstance.py:3312} INFO - 0 downstream tasks scheduled from follow-on schedule check
