[2024-04-05T13:46:25.513+0000] {taskinstance.py:1979} INFO - Dependencies all met for dep_context=non-requeueable deps ti=<TaskInstance: extract_osm_farmland.transform_load_togcs manual__2024-04-05T13:45:19.908430+00:00 [queued]>
[2024-04-05T13:46:25.530+0000] {taskinstance.py:1979} INFO - Dependencies all met for dep_context=requeueable deps ti=<TaskInstance: extract_osm_farmland.transform_load_togcs manual__2024-04-05T13:45:19.908430+00:00 [queued]>
[2024-04-05T13:46:25.531+0000] {taskinstance.py:2193} INFO - Starting attempt 1 of 2
[2024-04-05T13:46:25.561+0000] {taskinstance.py:2217} INFO - Executing <Task(_PythonDecoratedOperator): transform_load_togcs> on 2024-04-05 13:45:19.908430+00:00
[2024-04-05T13:46:25.570+0000] {standard_task_runner.py:60} INFO - Started process 4111 to run task
[2024-04-05T13:46:25.576+0000] {standard_task_runner.py:87} INFO - Running: ['***', 'tasks', 'run', 'extract_osm_farmland', 'transform_load_togcs', 'manual__2024-04-05T13:45:19.908430+00:00', '--job-id', '202', '--raw', '--subdir', 'DAGS_FOLDER/extract_file_data_from_osm.py', '--cfg-path', '/tmp/tmpouh03du4']
[2024-04-05T13:46:25.579+0000] {standard_task_runner.py:88} INFO - Job 202: Subtask transform_load_togcs
[2024-04-05T13:46:25.668+0000] {task_command.py:423} INFO - Running <TaskInstance: extract_osm_farmland.transform_load_togcs manual__2024-04-05T13:45:19.908430+00:00 [running]> on host 2adb4d880117
[2024-04-05T13:46:25.889+0000] {taskinstance.py:2513} INFO - Exporting env vars: AIRFLOW_CTX_DAG_OWNER='***' AIRFLOW_CTX_DAG_ID='extract_osm_farmland' AIRFLOW_CTX_TASK_ID='transform_load_togcs' AIRFLOW_CTX_EXECUTION_DATE='2024-04-05T13:45:19.908430+00:00' AIRFLOW_CTX_TRY_NUMBER='1' AIRFLOW_CTX_DAG_RUN_ID='manual__2024-04-05T13:45:19.908430+00:00'
[2024-04-05T14:10:31.089+0000] {geodataframe.py:635} ERROR - At line 7907, character 2636: Unterminated object
[2024-04-05T14:10:31.868+0000] {connectionpool.py:824} WARNING - Retrying (Retry(total=2, connect=None, read=None, redirect=None, status=None)) after connection broken by 'NewConnectionError('<urllib3.connection.HTTPSConnection object at 0x7fb57d426ac0>: Failed to establish a new connection: [Errno -2] Name or service not known')': /token
[2024-04-05T14:10:31.878+0000] {connectionpool.py:824} WARNING - Retrying (Retry(total=1, connect=None, read=None, redirect=None, status=None)) after connection broken by 'NewConnectionError('<urllib3.connection.HTTPSConnection object at 0x7fb57d426f40>: Failed to establish a new connection: [Errno -2] Name or service not known')': /token
[2024-04-05T14:10:31.886+0000] {connectionpool.py:824} WARNING - Retrying (Retry(total=0, connect=None, read=None, redirect=None, status=None)) after connection broken by 'NewConnectionError('<urllib3.connection.HTTPSConnection object at 0x7fb57d3fd2b0>: Failed to establish a new connection: [Errno -2] Name or service not known')': /token
[2024-04-05T14:10:31.955+0000] {connectionpool.py:824} WARNING - Retrying (Retry(total=2, connect=None, read=None, redirect=None, status=None)) after connection broken by 'NewConnectionError('<urllib3.connection.HTTPSConnection object at 0x7fb57d3fdc10>: Failed to establish a new connection: [Errno -2] Name or service not known')': /token
[2024-04-05T14:10:31.974+0000] {connectionpool.py:824} WARNING - Retrying (Retry(total=1, connect=None, read=None, redirect=None, status=None)) after connection broken by 'NewConnectionError('<urllib3.connection.HTTPSConnection object at 0x7fb57d40bf70>: Failed to establish a new connection: [Errno -2] Name or service not known')': /token
[2024-04-05T14:10:31.996+0000] {connectionpool.py:824} WARNING - Retrying (Retry(total=0, connect=None, read=None, redirect=None, status=None)) after connection broken by 'NewConnectionError('<urllib3.connection.HTTPSConnection object at 0x7fb57d40b3a0>: Failed to establish a new connection: [Errno -2] Name or service not known')': /token
[2024-04-05T14:10:33.289+0000] {connectionpool.py:824} WARNING - Retrying (Retry(total=2, connect=None, read=None, redirect=None, status=None)) after connection broken by 'NewConnectionError('<urllib3.connection.HTTPSConnection object at 0x7fb57d44fca0>: Failed to establish a new connection: [Errno -2] Name or service not known')': /token
[2024-04-05T14:10:33.297+0000] {connectionpool.py:824} WARNING - Retrying (Retry(total=1, connect=None, read=None, redirect=None, status=None)) after connection broken by 'NewConnectionError('<urllib3.connection.HTTPSConnection object at 0x7fb57d44f430>: Failed to establish a new connection: [Errno -2] Name or service not known')': /token
[2024-04-05T14:10:33.305+0000] {connectionpool.py:824} WARNING - Retrying (Retry(total=0, connect=None, read=None, redirect=None, status=None)) after connection broken by 'NewConnectionError('<urllib3.connection.HTTPSConnection object at 0x7fb57d44f6a0>: Failed to establish a new connection: [Errno -2] Name or service not known')': /token
[2024-04-05T14:10:33.895+0000] {connectionpool.py:824} WARNING - Retrying (Retry(total=2, connect=None, read=None, redirect=None, status=None)) after connection broken by 'NewConnectionError('<urllib3.connection.HTTPSConnection object at 0x7fb57d434a30>: Failed to establish a new connection: [Errno -2] Name or service not known')': /token
[2024-04-05T14:10:33.903+0000] {connectionpool.py:824} WARNING - Retrying (Retry(total=1, connect=None, read=None, redirect=None, status=None)) after connection broken by 'NewConnectionError('<urllib3.connection.HTTPSConnection object at 0x7fb57d434c10>: Failed to establish a new connection: [Errno -2] Name or service not known')': /token
[2024-04-05T14:10:33.910+0000] {connectionpool.py:824} WARNING - Retrying (Retry(total=0, connect=None, read=None, redirect=None, status=None)) after connection broken by 'NewConnectionError('<urllib3.connection.HTTPSConnection object at 0x7fb57d442340>: Failed to establish a new connection: [Errno -2] Name or service not known')': /token
[2024-04-05T14:10:39.374+0000] {connectionpool.py:824} WARNING - Retrying (Retry(total=2, connect=None, read=None, redirect=None, status=None)) after connection broken by 'NewConnectionError('<urllib3.connection.HTTPSConnection object at 0x7fb57d442700>: Failed to establish a new connection: [Errno -2] Name or service not known')': /token
[2024-04-05T14:10:39.392+0000] {connectionpool.py:824} WARNING - Retrying (Retry(total=1, connect=None, read=None, redirect=None, status=None)) after connection broken by 'NewConnectionError('<urllib3.connection.HTTPSConnection object at 0x7fb57d68cf70>: Failed to establish a new connection: [Errno -2] Name or service not known')': /token
[2024-04-05T14:10:39.402+0000] {connectionpool.py:824} WARNING - Retrying (Retry(total=0, connect=None, read=None, redirect=None, status=None)) after connection broken by 'NewConnectionError('<urllib3.connection.HTTPSConnection object at 0x7fb57d698970>: Failed to establish a new connection: [Errno -2] Name or service not known')': /token
[2024-04-05T14:10:45.527+0000] {connectionpool.py:824} WARNING - Retrying (Retry(total=2, connect=None, read=None, redirect=None, status=None)) after connection broken by 'NewConnectionError('<urllib3.connection.HTTPSConnection object at 0x7fb57d930370>: Failed to establish a new connection: [Errno -2] Name or service not known')': /token
[2024-04-05T14:10:45.536+0000] {connectionpool.py:824} WARNING - Retrying (Retry(total=1, connect=None, read=None, redirect=None, status=None)) after connection broken by 'NewConnectionError('<urllib3.connection.HTTPSConnection object at 0x7fb595ec64f0>: Failed to establish a new connection: [Errno -2] Name or service not known')': /token
[2024-04-05T14:10:45.547+0000] {connectionpool.py:824} WARNING - Retrying (Retry(total=0, connect=None, read=None, redirect=None, status=None)) after connection broken by 'NewConnectionError('<urllib3.connection.HTTPSConnection object at 0x7fb595e240d0>: Failed to establish a new connection: [Errno -2] Name or service not known')': /token
[2024-04-05T14:10:49.647+0000] {connectionpool.py:824} WARNING - Retrying (Retry(total=2, connect=None, read=None, redirect=None, status=None)) after connection broken by 'NewConnectionError('<urllib3.connection.HTTPSConnection object at 0x7fb57d22e2e0>: Failed to establish a new connection: [Errno -2] Name or service not known')': /token
[2024-04-05T14:10:49.657+0000] {connectionpool.py:824} WARNING - Retrying (Retry(total=1, connect=None, read=None, redirect=None, status=None)) after connection broken by 'NewConnectionError('<urllib3.connection.HTTPSConnection object at 0x7fb57d22e5b0>: Failed to establish a new connection: [Errno -2] Name or service not known')': /token
[2024-04-05T14:10:49.665+0000] {connectionpool.py:824} WARNING - Retrying (Retry(total=0, connect=None, read=None, redirect=None, status=None)) after connection broken by 'NewConnectionError('<urllib3.connection.HTTPSConnection object at 0x7fb57d1c0460>: Failed to establish a new connection: [Errno -2] Name or service not known')': /token
[2024-04-05T14:10:54.949+0000] {connectionpool.py:824} WARNING - Retrying (Retry(total=2, connect=None, read=None, redirect=None, status=None)) after connection broken by 'NewConnectionError('<urllib3.connection.HTTPSConnection object at 0x7fb579ec7400>: Failed to establish a new connection: [Errno -2] Name or service not known')': /token
[2024-04-05T14:10:54.956+0000] {connectionpool.py:824} WARNING - Retrying (Retry(total=1, connect=None, read=None, redirect=None, status=None)) after connection broken by 'NewConnectionError('<urllib3.connection.HTTPSConnection object at 0x7fb579ec74c0>: Failed to establish a new connection: [Errno -2] Name or service not known')': /token
[2024-04-05T14:10:54.965+0000] {connectionpool.py:824} WARNING - Retrying (Retry(total=0, connect=None, read=None, redirect=None, status=None)) after connection broken by 'NewConnectionError('<urllib3.connection.HTTPSConnection object at 0x7fb579ec76a0>: Failed to establish a new connection: [Errno -2] Name or service not known')': /token
[2024-04-05T14:11:14.024+0000] {connectionpool.py:824} WARNING - Retrying (Retry(total=2, connect=None, read=None, redirect=None, status=None)) after connection broken by 'NewConnectionError('<urllib3.connection.HTTPSConnection object at 0x7fb579ec7f10>: Failed to establish a new connection: [Errno -2] Name or service not known')': /token
[2024-04-05T14:11:14.033+0000] {connectionpool.py:824} WARNING - Retrying (Retry(total=1, connect=None, read=None, redirect=None, status=None)) after connection broken by 'NewConnectionError('<urllib3.connection.HTTPSConnection object at 0x7fb579eb60a0>: Failed to establish a new connection: [Errno -2] Name or service not known')': /token
[2024-04-05T14:11:14.041+0000] {connectionpool.py:824} WARNING - Retrying (Retry(total=0, connect=None, read=None, redirect=None, status=None)) after connection broken by 'NewConnectionError('<urllib3.connection.HTTPSConnection object at 0x7fb579eb62e0>: Failed to establish a new connection: [Errno -2] Name or service not known')': /token
[2024-04-05T14:12:25.993+0000] {logging_mixin.py:188} INFO - DataFrame uploaded to GCS: gs://sammy_project_bucket2024/Nigeria_farmland.geojson
[2024-04-05T14:12:26.023+0000] {python.py:202} INFO - Done. Returned value was: gs://sammy_project_bucket2024/Nigeria_farmland.geojson
[2024-04-05T14:12:26.064+0000] {taskinstance.py:1149} INFO - Marking task as SUCCESS. dag_id=extract_osm_farmland, task_id=transform_load_togcs, execution_date=20240405T134519, start_date=20240405T134625, end_date=20240405T141226
[2024-04-05T14:12:26.148+0000] {local_task_job_runner.py:234} INFO - Task exited with return code 0
[2024-04-05T14:12:26.215+0000] {taskinstance.py:3312} INFO - 1 downstream tasks scheduled from follow-on schedule check
